Workbook
Name suma: 'Estimar CostosxHora'!$Q$6

Sheet Estimar CostosxHora
A1: PLANTILLA AYUDA PARA COSTOS | Q1: PLANTILLA COSTOS
A2: Módulo / Épica | B2: Id. Act | C2: Actividad /Tarea | D2: Tipo de recurso (Personal, Materiales, Equipo) | E2: Recursos | H2: Disponibilidad de Cada Recurso ( Capacidad Maxima por día) (%,horas) | I2: p | J2: m | K2: o | L2: Esfuerzo (pert) horas | M2: Desviación (p-0)/6 | N2: Duración de actividad(esfuerzo en horas) | O2: Capacidad Máxima (% Horas¨dia) | P2: Disponibilidad Recurso Horas al dia | Q2: Costo recurso por hora | R2: Costo por actividad | S2: costo por W.P
A3: Autenticación y Perfil | B3: AU-01 | C3: Registro de usuario + validación + email | D3: Personal | E3: Desarrollador | H3: 0.5 | I3: 15 | J3: 14 | K3: 8 | L3: =(I3+4*J3+K3)/6 -> 13.166667 | M3: =(I3-K3)/6 -> 1.1666667 | N3: =(L3+M3)*8 -> 114.66667 | O3: 0.5 | P3: =N3*O3 -> 57.333333 | Q3: 441.864 | R3: =N3*Q3 -> 50667.072
B4: AU-02 | C4: Login y recuperación de contraseña | D4: Personal | E4: Desarrollador | H4: 0.5 | I4: 12 | J4: 8 | K4: 4 | L4: =(I4+4*J4+K4)/6 -> 8 | M4: =(I4-K4)/6 -> 1.3333333 | N4: =(L4+M4)*8 -> 74.666667 | O4: 0.5 | P4: =O4*Presupuesto!$B$5 -> 8 | Q4: 441.864 | R4: =N4*Q4 -> 32992.512
B5: AU-03 | C5: Autenticacion | D5: Personal | E5: Product Owner | H5: 1 | I5: 5 | J5: 3 | K5: 1 | L5: =(I5+4*J5+K5)/6 -> 3 | M5: =(I5-K5)/6 -> 0.66666667 | N5: =(L5+M5)*8 -> 29.333333 | O5: 1 | P5: =O5*Presupuesto!$B$5 -> 16 | Q5: 445.74 | R5: =N5*Q5 -> 13075.04 | S5: =SUM(R3:R5) -> 96734.624
A6: Gestión de Citas | B6: GC-01 | C6: Agendamiento con disponibilidad en tiempo real | D6: Personal | E6: Desarrollador | H6: 0.5 | I6: 15 | J6: 22 | K6: 14 | L6: =(I6+4*J6+K6)/6 -> 19.5 | M6: =(I6-K6)/6 -> 0.16666667 | N6: =(L6+M6)*8 -> 157.33333 | O6: 0.5 | P6: =O6*Presupuesto!$B$5 -> 8 | Q6: 441.864 | R6: =N6*Q6 -> 69519.936
B7: GC-02 | C7: Cancelación/reprogramación con regla de 12h | D7: Personal | E7: Desarrollador | H7: 0.5 | I7: 16 | J7: 10 | K7: 6 | L7: =(I7+4*J7+K7)/6 -> 10.333333 | M7: =(I7-K7)/6 -> 1.6666667 | N7: =(L7+M7)*8 -> 96 | O7: 0.5 | P7: =O7*Presupuesto!$B$5 -> 8 | Q7: 441.864 | R7: =N7*Q7 -> 42418.944
B8: GC-03 | C8: Notificaciones Push/SMS 24h antes de la cita | D8: Personal | E8: Desarrollador | H8: 0.5 | I8: 10 | J8: 7 | K8: 4 | L8: =(I8+4*J8+K8)/6 -> 7 | M8: =(I8-K8)/6 -> 1 | N8: =(L8+M8)*8 -> 64 | O8: 0.5 | P8: =O8*Presupuesto!$B$5 -> 8 | Q8: 441.864 | R8: =N8*Q8 -> 28279.296
B9: GC-04 | C9: Criterios de aceptación | D9: Personal | E9: Product Owner | H9: 1 | I9: 7 | J9: 3 | K9: 2 | L9: =(I9+4*J9+K9)/6 -> 3.5 | M9: =(I9-K9)/6 -> 0.83333333 | N9: =(L9+M9)*8 -> 34.666667 | O9: 1 | P9: =O9*Presupuesto!$B$5 -> 16 | Q9: 445.74 | R9: =N9*Q9 -> 15452.32 | S9: =SUM(R6:R9) -> 155670.5
A10: Historial y Fórmulas | B10: HF-01 | C10: Historial clínico en PDF con filtros | D10: Personal | E10: Desarrollador | H10: 0.5 | I10: 20 | J10: 18 | K10: 10 | L10: =(I10+4*J10+K10)/6 -> 17 | M10: =(I10-K10)/6 -> 1.6666667 | N10: =(L10+M10)*8 -> 149.33333 | O10: 0.5 | P10: =O10*Presupuesto!$B$5 -> 8 | Q10: 441.864 | R10: =N10*Q10 -> 65985.024
B11: HF-02 | C11: Fórmulas digitales con QR y vigencia | D11: Personal | E11: Desarrollador | H11: 0.5 | I11: 16 | J11: 12 | K11: 8 | L11: =(I11+4*J11+K11)/6 -> 12 | M11: =(I11-K11)/6 -> 1.3333333 | N11: =(L11+M11)*8 -> 106.66667 | O11: 0.5 | P11: =O11*Presupuesto!$B$5 -> 8 | Q11: 441.864 | R11: =N11*Q11 -> 47132.16
B12: HF-03 | C12: Notificación automática de vencimiento | D12: Personal | E12: Desarrollador | H12: 0.5 | I12: 8 | J12: 6 | K12: 3 | L12: =(I12+4*J12+K12)/6 -> 5.8333333 | M12: =(I12-K12)/6 -> 0.83333333 | N12: =(L12+M12)*8 -> 53.333333 | O12: 0.5 | P12: =O12*Presupuesto!$B$5 -> 8 | Q12: 441.864 | R12: =N12*Q12 -> 23566.08 | S12: =SUM(R10:R12) -> 136683.26
A13: Telemedicina y Emergencias | B13: TE-01 | C13: Pasarela de vídeo segura con chat y fotos | D13: Personal | E13: Desarrollador | H13: 0.5 | I13: 40 | J13: 28 | K13: 16 | L13: =(I13+4*J13+K13)/6 -> 28 | M13: =(I13-K13)/6 -> 4 | N13: =(L13+M13)*8 -> 256 | O13: 0.5 | P13: =O13*Presupuesto!$B$5 -> 8 | Q13: 441.864 | R13: =N13*Q13 -> 113117.18
B14: TE-02 | C14: Botón de emergencia con GPS y contactos | D14: Personal | E14: Desarrollador | H14: 0.5 | I14: 20 | J14: 14 | K14: 8 | L14: =(I14+4*J14+K14)/6 -> 14 | M14: =(I14-K14)/6 -> 2 | N14: =(L14+M14)*8 -> 128 | O14: 0.5 | P14: =O14*Presupuesto!$B$5 -> 8 | Q14: 441.864 | R14: =N14*Q14 -> 56558.592
B15: TE-03 | C15: Acceso de emergencia sin desbloqueo de perfil | D15: Personal | E15: Desarrollador | H15: 0.5 | I15: 12 | J15: 8 | K15: 4 | L15: =(I15+4*J15+K15)/6 -> 8 | M15: =(I15-K15)/6 -> 1.3333333 | N15: =(L15+M15)*8 -> 74.666667 | O15: 0.5 | P15: =O15*Presupuesto!$B$5 -> 8 | Q15: 441.864 | R15: =N15*Q15 -> 32992.512 | S15: =SUM(R13:R15) -> 202668.29
A16: Módulo Médicos | B16: MM-01 | C16: Agenda cronológica con estado del paciente | D16: Personal | E16: Desarrollador | H16: 0.5 | I16: 16 | J16: 12 | K16: 6 | L16: =(I16+4*J16+K16)/6 -> 11.666667 | M16: =(I16-K16)/6 -> 1.6666667 | N16: =(L16+M16)*8 -> 106.66667 | O16: 0.5 | P16: =O16*Presupuesto!$B$5 -> 8 | Q16: 441.864 | R16: =N16*Q16 -> 47132.16
B17: MM-02 | C17: Historial con log de auditoría | D17: Personal | E17: Desarrollador | H17: 0.5 | I17: 14 | J17: 10 | K17: 6 | L17: =(I17+4*J17+K17)/6 -> 10 | M17: =(I17-K17)/6 -> 1.3333333 | N17: =(L17+M17)*8 -> 90.666667 | O17: 0.5 | P17: =O17*Presupuesto!$B$5 -> 8 | Q17: 441.864 | R17: =N17*Q17 -> 40062.336
B18: MM-03 | C18: Diagnósticos CIE-10 con autoguardado | D18: Personal | E18: Desarrollador | H18: 0.5 | I18: 18 | J18: 13 | K18: 8 | L18: =(I18+4*J18+K18)/6 -> 13 | M18: =(I18-K18)/6 -> 1.6666667 | N18: =(L18+M18)*8 -> 117.33333 | O18: 0.5 | P18: =O18*Presupuesto!$B$5 -> 8 | Q18: 441.864 | R18: =N18*Q18 -> 51845.376
B19: MM-04 | C19: Incapacidades con firma digital | D19: Personal | E19: Desarrollador | H19: 0.5 | I19: 16 | J19: 11 | K19: 6 | L19: =(I19+4*J19+K19)/6 -> 11 | M19: =(I19-K19)/6 -> 1.6666667 | N19: =(L19+M19)*8 -> 101.33333 | O19: 0.5 | P19: =O19*Presupuesto!$B$5 -> 8 | Q19: 441.864 | R19: =N19*Q19 -> 44775.552 | S19: =SUM(R16:R19) -> 183815.42
A20: Módulo Administrativo | B20: MA-01 | C20: Panel de gestión de citas con estados | D20: Personal | E20: Desarrollador | H20: 0.5 | I20: 14 | J20: 10 | K20: 6 | L20: =(I20+4*J20+K20)/6 -> 10 | M20: =(I20-K20)/6 -> 1.3333333 | N20: =(L20+M20)*8 -> 90.666667 | O20: 0.5 | P20: =O20*Presupuesto!$B$5 -> 8 | Q20: 441.864 | R20: =N20*Q20 -> 40062.336
B21: MA-02 | C21: Aprobación de medicamentos + inventario farmacia | D21: Personal | E21: Desarrollador | H21: 0.5 | I21: 16 | J21: 11 | K21: 6 | L21: =(I21+4*J21+K21)/6 -> 11 | M21: =(I21-K21)/6 -> 1.6666667 | N21: =(L21+M21)*8 -> 101.33333 | O21: 0.5 | P21: =O21*Presupuesto!$B$5 -> 8 | Q21: 441.864 | R21: =N21*Q21 -> 44775.552
B22: MA-03 | C22: Consulta de trámites por identificación | D22: Personal | E22: Desarrollador | H22: 0.5 | I22: 10 | J22: 7 | K22: 4 | L22: =(I22+4*J22+K22)/6 -> 7 | M22: =(I22-K22)/6 -> 1 | N22: =(L22+M22)*8 -> 64 | O22: 0.5 | P22: =O22*Presupuesto!$B$5 -> 8 | Q22: 441.864 | R22: =N22*Q22 -> 28279.296
B23: MA-04 | C23: Registro de clínicas con geolocalización | D23: Personal | E23: Desarrollador | H23: 0.5 | I23: 12 | J23: 8 | K23: 4 | L23: =(I23+4*J23+K23)/6 -> 8 | M23: =(I23-K23)/6 -> 1.3333333 | N23: =(L23+M23)*8 -> 74.666667 | O23: 0.5 | P23: =O23*Presupuesto!$B$5 -> 8 | Q23: 441.864 | R23: =N23*Q23 -> 32992.512 | S23: =SUM(R20:R23) -> 146109.7
A24: Sistema e Infraestructura | B24: SI-01 | C24: Encriptación en reposo y en tránsito SSL/HTTPS | D24: Personal | E24: Desarrollador | H24: 0.5 | I24: 20 | J24: 14 | K24: 8 | L24: =(I24+4*J24+K24)/6 -> 14 | M24: =(I24-K24)/6 -> 2 | N24: =(L24+M24)*8 -> 128 | O24: 0.5 | P24: =O24*Presupuesto!$B$5 -> 8 | Q24: 441.864 | R24: =N24*Q24 -> 56558.592
B25: SI-02 | C25: Proceso background notificaciones automáticas | D25: Personal | E25: Desarrollador | H25: 0.5 | I25: 12 | J25: 8 | K25: 4 | L25: =(I25+4*J25+K25)/6 -> 8 | M25: =(I25-K25)/6 -> 1.3333333 | N25: =(L25+M25)*8 -> 74.666667 | O25: 0.5 | P25: =O25*Presupuesto!$B$5 -> 8 | Q25: 441.864 | R25: =N25*Q25 -> 32992.512 | S25: =SUM(R24:R25) -> 89551.104
A26: Gestión del Proyecto | B26: GP-01 | C26: Planificación y gestión del backlog del proyecto | D26: Personal | E26: Product Manager | H26: 1 | I26: 25 | J26: 20 | K26: 10 | L26: =(I26+4*J26+K26)/6 -> 19.166667 | M26: =(I26-K26)/6 -> 2.5 | N26: =(L26+M26)*8 -> 173.33333 | O26: 1 | P26: =O26*Presupuesto!$B$5 -> 16 | Q26: 733.533 | R26: =N26*Q26 -> 127145.72
B27: GP-02 | C27: Revisión de HU y criterios de aceptación | D27: Personal | E27: Product Owner | H27: 1 | I27: 10 | J27: 9 | K27: 7 | L27: =(I27+4*J27+K27)/6 -> 8.8333333 | M27: =(I27-K27)/6 -> 0.5 | N27: =(L27+M27)*8 -> 74.666667 | O27: 1 | P27: =O27*Presupuesto!$B$5 -> 16 | Q27: 445.74 | R27: =N27*Q27 -> 33281.92
S28: =SUM(R26:R27) -> 160427.64

Sheet Estimar por puntos de historia
A1: PLANTILLA DE AYUDA PARA ESTIMACIÓN | E1: PLANTILLA COSTOS
A2: Módulo / Épica | B2: HU | C2: Actividad /Tarea | D2: Punto de historia | E2: Costo punto de historia | F2: Costo por actividad | G2: costo por Módulo/Épica
A3: Autenticación y Perfil | B3: Como paciente quiero registrarme en la app para acceder a los servicios de salud | C3: Diseño e impl. formulario de registro (nombre, cédula, correo, EPS) + validación | D3: 3 | E3: 858358 | F3: =E3*D3 -> 2575074
C4: Login con validación de credenciales, verificación de usuario y recuperación de contraseña vía email | D4: 2 | E4: 858358 | F4: =E4*D4 -> 1716716
C5: Actualización de datos personales (campos no críticos) con reflejo inmediato | D5: 2 | E5: 858358 | F5: =E5*D5 -> 1716716 | G5: =SUM(F3:F5) -> 6008506
A6: Gestión de Citas | B6: Como paciente quiero agendar una cita médica para verificar mi salud | C6: Flujo de agendamiento con especialidades y validación de horarios duplicados | D6: 5 | E6: 858358 | F6: =E6*D6 -> 4291790
C7: Visualización de disponibilidad de médicos en tiempo real | D7: 3 | E7: 858358 | F7: =E7*D7 -> 2575074
C8: Cancelación/reprogramación hasta 12h antes + liberación inmediata del horario | D8: 3 | E8: 858358 | F8: =E8*D8 -> 2575074
B9: Como administrativo quiero ver solicitudes de citas para gestionarlas y asignarlas | C9: Panel de gestión con estados: Aprobada, Rechazada o Pendiente | D9: 5 | E9: 858358 | F9: =E9*D9 -> 4291790 | G9: =SUM(F6:F9) -> 13733728
A10: Historial Clínico y Fórmulas | B10: Como paciente quiero ver mi historial clínico para conocer mis tratamientos | C10: Visualización de historial en formato PDF con filtros por fecha y médico | D10: 5 | E10: 858358 | F10: =E10*D10 -> 4291790
C11: Fórmulas médicas digitales con código QR/barras y fecha de vigencia | D11: 5 | E11: 858358 | F11: =E11*D11 -> 4291790
C12: Notificación automática 2 días antes del vencimiento de fórmula recurrente | D12: 2 | E12: 858358 | F12: =E12*D12 -> 1716716 | G12: =SUM(F10:F12) -> 10300296
A13: Telemedicina y Emergencias | B13: Como paciente quiero telemedicina para no tener que ir a la clínica | C13: Integración de pasarela de vídeo segura con chat y adjuntos de fotos | D13: 13 | E13: 858358 | F13: =E13*D13 -> 11158654
C14: Botón de emergencia: envío de ubicación GPS y notificación a 3 contactos | D14: 13 | E14: 858358 | F14: =E14*D14 -> 11158654
C15: Acceso de emergencia a alergias y tipo de sangre sin desbloquear perfil | D15: 8 | E15: 858358 | F15: =E15*D15 -> 6866864 | G15: =SUM(F13:F15) -> 29184172
A16: Módulo Médicos | B16: Como médico quiero ver mi agenda para organizarme en la jornada | C16: Agenda cronológica con estado de llegada del paciente (en espera / atendido) | D16: 3 | E16: 858358 | F16: =E16*D16 -> 2575074
C17: Acceso a historial clínico con log de auditoría (solo pacientes del día) | D17: 5 | E17: 858358 | F17: =E17*D17 -> 4291790
C18: Registro de diagnósticos con codificación CIE-10 y autoguardado | D18: 5 | E18: 858358 | F18: =E18*D18 -> 4291790
C19: Generación de incapacidades médicas con firma digital válida legalmente | D19: 8 | E19: 858358 | F19: =E19*D19 -> 6866864
C20: Aprobación de medicamentos con verificación de inventario de farmacia vinculada | D20: 5 | E20: 858358 | F20: =E20*D20 -> 4291790
C21: Consulta de estado de trámites por número de identificación del usuario | D21: 3 | E21: 858358 | F21: =E21*D21 -> 2575074
C22: Registro de clínicas/centros de salud con geolocalización (lat/long) para mapa | D22: 5 | E22: 858358 | F22: =E22*D22 -> 4291790 | G22: =SUM(F16:F22) -> 29184172
A23: Sistema e Infraestructura | B23: Como sistema quiero almacenar datos de forma segura | C23: Encriptación en reposo (BD) y en tránsito (SSL/HTTPS) | D23: 8 | E23: 858358 | F23: =E23*D23 -> 6866864
C24: Proceso background de notificaciones automáticas sin intervención humana | D24: 3 | E24: 858358 | F24: =E24*D24 -> 2575074 | G24: =SUM(F23:F24) -> 9441938
A25: Formulación Digital | B25: Como médico quiero generar recetas médicas con firma digital | C25: Generación de receta médica con firma digital válida legalmente y exportable en PDF | D25: 8 | E25: 858358 | F25: =E25*D25 -> 6866864
C26: Operador farmacéutico visualiza fórmulas pendientes y marca medicamentos como preparados | D26: 5 | E26: 858358 | F26: =E26*D26 -> 4291790 | G26: =SUM(F25:F26) -> 11158654
A27: Notificaciones | B27: Como paciente quiero notificaciones de mis citas para no olvidarlas | C27: Envío de SMS/Push 24h antes de la cita al paciente | D27: 3 | E27: 858358 | F27: =E27*D27 -> 2575074 | G27: =F27 -> 2575074
A28: Afiliación | B28: Como administrativo quiero validar si el usuario está en Régimen Contributivo o Subsidiado | C28: Verificación en tiempo real con BDUA/Sisbén y confirmación de pagos realizados | D28: 8 | E28: 858358 | F28: =E28*D28 -> 6866864 | G28: =F28 -> 6866864
A29: Reportes | B29: Como sistema quiero generar reportes de aportes del 12% para el Régimen Contributivo | C29: Generación de reportes de aportes con auditorías semestrales | D29: 5 | E29: 858358 | F29: =E29*D29 -> 4291790 | G29: =F29 -> 4291790
A30: UI/UX | B30: Como paciente quiero que la app use la paleta y tipografía de SURA | C30: Implementación de guías de marca SURA + accesibilidad para adultos mayores | D30: 3 | E30: 858358 | F30: =E30*D30 -> 2575074 | G30: =F30 -> 2575074
A32: TOTAL | D32: =SUM(D3:D30) -> 146 | E32: =SUM(E3:E30) -> 24034024 | F32: =SUM(F3:F30) -> 125320268 | G32: =SUM(G5:G30) -> 125320268

Sheet Presupuesto
A2: INDEMNIZACIONES | B2: 0.02
A3: DURACIÓN DEL PROYECTO MESES | B3: 4
A4: RESERVA GERENCIAL | B4: 0.05
A5: HORAS A TRABAJAR POR MES | B5: 16
A7: Alternativa Esquema Actual
A8: NOMINA
A9: CARGO | B9: CANTIDAD | C9: SALARIO | D9: INCENTIVOS | E9: PRESTACIONES | F9: COSTO + INDEM | G9: COSTO HORA | H9: COSTO MENSUAL
A10: Product Owner | B10: 2 | C10: 4500000 | D10: 100000 | E10: =(C10+D10)*0.52 -> 2392000 | F10: =(C10+E10+D10)*(1+$B$2) -> 7131840 | G10: =F10/$B$5 -> 445740 | H10: =F10*B10 -> 14263680
A11: Product Manager | B11: 1 | C11: 7500000 | D11: 70000 | E11: =(C11+D11)*0.52 -> 3936400 | F11: =(C11+E11+D11)*(1+$B$2) -> 11736528 | G11: =F11/$B$5 -> 733533 | H11: =F11*B11 -> 11736528
A12: Desarrollador | B12: 3 | C12: 4500000 | D12: 60000 | E12: =(C12+D12)*0.52 -> 2371200 | F12: =(C12+E12+D12)*(1+$B$2) -> 7069824 | G12: =F12/$B$5 -> 441864 | H12: =F12*B12 -> 21209472
A28: Cantidad de personal | B28: =SUM(B10:B27) -> 6 | F28: ESTIMADO MENSUAL | H28: =SUM(H10:H27) -> 47209680
E29: TOTAL ESTIMADO PROYECTO | H29: =H28*B3 -> 188838720
A33: OTROS COSTOS
A34: ITEM | B34: TIPO(Directo/Indirecto) | C34: CANTIDAD | D34: COSTO UNITARIO | E34: COSTO TOTAL
A35: Servidor a la nube por mes (10 euros 41.521,50 COP) | B35: Directo | C35: 4 | D35: 42000 | E35: =C35*D35 -> 168000
A36: Servicio de videollamada (Daily.co o Agora) | B36: Directo | C36: 4 | D36: 215000 | E36: =C36*D36 -> 860000
A37: Google Maps API | B37: Directo | C37: 4 | D37: 85000 | E37: =C37*D37 -> 340000
A38: Twilio SMS/Push notifications | B38: Directo | C38: 4 | D38: 85000 | E38: =C38*D38 -> 340000
E39: =C39*D39 -> 0
E40: =C40*D40 -> 0
E41: =C41*D41 -> 0
E42: =C42*D42 -> 0
E43: =C43*D43 -> 0
E44: =C44*D44 -> 0
E45: =C45*D45 -> 0
E46: =C46*D46 -> 0
E47: =C47*D47 -> 0
E48: =C48*D48 -> 0
D49: TOTAL OTROS COSTOS | E49: =SUM(E35:E48) -> 1708000
A53: TIPO DE RESERVA CONTINGENCIA | B53: VALOR
A54: Horas extra dominicales y festivas | B54: =SUM(G10:G12) -> 1621137
B55: $
B56: $
B57: $
B58: $
B59: $
B60: $
B61: $
A62: TOTAL DE LA RESERVA CONTINGENCIA | B62: =SUM(B54:B61) -> 1621137
A64: ESTIMADO RECURSO HUMANO | B64: =H29 -> 188838720
...

Sheet costo por recurso o punto de H
F2: Datos a tener en cuenta
F3: Salario mínimo 2025 | G3: 1750905
F4: Subsidio de transporte | G4: 249095 | H4: Hasta dos salarios mínimos
A5: Inversión mensual por trabajador
A6: Concepto | B6: % | C6: Monto
A7: Horas trabajadas mensuales | C7: 16
A8: Salario base | C8: 2600000
A9: Subsidio de transporte | C9: 0
A10: Salario Mensual | C10: =SUM(C8:C9) -> 2600000
A12: Prima Legal | B12: 0.0833 | C12: =C$8*B12 -> 216580
A13: Cesantias | B13: 0.0833 | C13: =C$8*B13 -> 216580
A14: Intereses a las cesantias | B14: 0.0012 | C14: =C$8*B14 -> 3120
A15: Vacaciones | B15: 0.04167 | C15: =C$8*B15 -> 108342
A17: Total prestaciones | B17: =SUM(B12:B15) -> 0.20947 | C17: =SUM(C12:C16) -> 544622
A19: Aportes a salud | B19: 0.085 | C19: =C$8*B19 -> 221000
A20: Aportes a pensión | B20: 0.12 | C20: =C$8*B20 -> 312000
A21: Parafiscales | B21: 0.09 | C21: =C$8*B21 -> 234000
A22: ARL Riesgo Administrativo | B22: 0.00522 | C22: =C$8*B22 -> 13572
A24: Total Aportes | B24: =SUM(B19:B23) -> 0.30022 | C24: =SUM(C19:C23) -> 780572
A26: Total Mensual | C26: =C10+C17+C24 -> 3925194
A27: Total Anual | C27: =C26*12 -> 47102328
A28: Total Hora | C28: =C26/C7 -> 245324.62
A33: Total puntos de historia proyecto | B33: 146
A34: Puntos de historia por mes | B34: 55
A35: Costo del equipo por mes | B35: =Presupuesto!H28 -> 47209680
A36: Valor del punto de historia por mes | B36: =B35/B34 -> 858357.82
A37: Valor del esfuerzo | B37: =B33*B36 -> 1.2532024e+08
